2020-10-09 13:14:48,959 INFO Starting server at `/home/dbhost/Work/test_django2/.`.
2020-10-09 13:14:48,960 DEBUG Trying to acquire lock on file /home/dbhost/Work/test_django2/.pyre/client.lock
2020-10-09 13:14:48,960 DEBUG Daemonizing the configuration_monitor.
2020-10-09 13:14:48,960 DEBUG Trying to acquire lock on file /home/dbhost/Work/test_django2/.pyre/server/server.lock
2020-10-09 13:14:48,961 DEBUG Unable to acquire lock because lock file /home/dbhost/Work/test_django2/.pyre/server/server.lock was not found
2020-10-09 13:14:48,961 DEBUG Running `/home/dbhost/Work/test_django2/env/bin/pyre.bin start -logging-sections environment -project-root /home/dbhost/Work/test_django2 -log-directory /home/dbhost/Work/test_django2/.pyre -taint-models /home/dbhost/Work/test_django2/env/lib -filter-directories /home/dbhost/Work/test_django2/. -workers 1 -expected-binary-version unversioned -search-path /home/dbhost/Work/test_django2/env/lib/pyre_check/typeshed/stdlib/3.9,/home/dbhost/Work/test_django2/env/lib/pyre_check/typeshed/stdlib/3.7,/home/dbhost/Work/test_django2/env/lib/pyre_check/typeshed/stdlib/3.6,/home/dbhost/Work/test_django2/env/lib/pyre_check/typeshed/stdlib/3,/home/dbhost/Work/test_django2/env/lib/pyre_check/typeshed/stdlib/2and3,/home/dbhost/Work/test_django2/env/lib/pyre_check/typeshed/third_party/3,/home/dbhost/Work/test_django2/env/lib/pyre_check/typeshed/third_party/2and3 -new-incremental-check /home/dbhost/Work/test_django2/.`
2020-10-09 13:14:49,030 DEBUG Trying to acquire lock on file /home/dbhost/Work/test_django2/.pyre/configuration_monitor/configuration_monitor.lock
2020-10-09 13:14:49,054 DEBUG Registering process with pid 44843 in pid file `/home/dbhost/Work/test_django2/.pyre/configuration_monitor/configuration_monitor.pid`
2020-10-09 13:14:49,054 DEBUG Registering process with pid 44842 in pid file `/home/dbhost/Work/test_django2/.pyre/pid_files/start-44842.pid`
2020-10-09 13:14:49,068 INFO Starting up server ...
2020-10-09 13:14:49,068 INFO Running as pid: 44842
2020-10-09 13:14:49,068 INFO Version: f319efebe90e67e4220339e10efa6ee3155537ad
2020-10-09 13:14:49,068 INFO Build info: Linux x86_64 @ Thu Sep 24 17:22:29 PDT 2020
2020-10-09 13:14:49,069 INFO Server starting in background
2020-10-09 13:14:49,071 DEBUG Removing pid file: `/home/dbhost/Work/test_django2/.pyre/pid_files/start-44842.pid`
2020-10-09 13:16:20,371 DEBUG Removing pid file: `/home/dbhost/Work/test_django2/.pyre/configuration_monitor/configuration_monitor.pid`
2020-10-09 13:16:20,372 WARNING Interrupted by user

2020-10-09 13:16:20,374 DEBUG Traceback (most recent call last):
  File "/home/dbhost/Work/test_django2/env/lib/python3.8/site-packages/pyre_check/client/pyre.py", line 125, in run_pyre
    exit_code = command.run().exit_code()
  File "/home/dbhost/Work/test_django2/env/lib/python3.8/site-packages/pyre_check/client/commands/command.py", line 407, in run
    self._run()
  File "/home/dbhost/Work/test_django2/env/lib/python3.8/site-packages/pyre_check/client/commands/incremental.py", line 106, in _run
    Start(
  File "/home/dbhost/Work/test_django2/env/lib/python3.8/site-packages/pyre_check/client/commands/command.py", line 407, in run
    self._run()
  File "/home/dbhost/Work/test_django2/env/lib/python3.8/site-packages/pyre_check/client/commands/start.py", line 116, in _run
    self._start_configuration_monitor()
  File "/home/dbhost/Work/test_django2/env/lib/python3.8/site-packages/pyre_check/client/commands/start.py", line 98, in _start_configuration_monitor
    configuration_monitor.ConfigurationMonitor(
  File "/home/dbhost/Work/test_django2/env/lib/python3.8/site-packages/pyre_check/client/watchman.py", line 159, in daemonize
    self._run()
  File "/home/dbhost/Work/test_django2/env/lib/python3.8/site-packages/pyre_check/client/watchman.py", line 129, in _run
    response = connection.receive()
  File "/home/dbhost/Work/test_django2/env/lib/python3.8/site-packages/pywatchman/__init__.py", line 695, in receive
    buf = [self.transport.readBytes(sniff_len)]
  File "/home/dbhost/Work/test_django2/env/lib/python3.8/site-packages/pywatchman/__init__.py", line 339, in readBytes
    buf = [self.sock.recv(size)]
KeyboardInterrupt

2020-10-09 13:16:20,377 WARNING Interrupted by user

2020-10-09 13:16:20,380 DEBUG Traceback (most recent call last):
  File "/home/dbhost/Work/test_django2/env/lib/python3.8/site-packages/pyre_check/client/pyre.py", line 125, in run_pyre
    exit_code = command.run().exit_code()
  File "/home/dbhost/Work/test_django2/env/lib/python3.8/site-packages/pyre_check/client/commands/command.py", line 407, in run
    self._run()
  File "/home/dbhost/Work/test_django2/env/lib/python3.8/site-packages/pyre_check/client/commands/incremental.py", line 106, in _run
    Start(
  File "/home/dbhost/Work/test_django2/env/lib/python3.8/site-packages/pyre_check/client/commands/command.py", line 407, in run
    self._run()
  File "/home/dbhost/Work/test_django2/env/lib/python3.8/site-packages/pyre_check/client/commands/start.py", line 143, in _run
    file_monitor = project_files_monitor.ProjectFilesMonitor(
  File "/home/dbhost/Work/test_django2/env/lib/python3.8/site-packages/pyre_check/client/project_files_monitor.py", line 66, in __init__
    self.socket_connection.perform_handshake(self._configuration.version_hash)
  File "/home/dbhost/Work/test_django2/env/lib/python3.8/site-packages/pyre_check/client/socket_connection.py", line 45, in perform_handshake
    json_rpc.perform_handshake(self.input, self.output, version_hash)
  File "/home/dbhost/Work/test_django2/env/lib/python3.8/site-packages/pyre_check/client/json_rpc.py", line 168, in perform_handshake
    server_handshake = read_request(input_file)
  File "/home/dbhost/Work/test_django2/env/lib/python3.8/site-packages/pyre_check/client/json_rpc.py", line 144, in read_request
    payload = _read_payload(file)
  File "/home/dbhost/Work/test_django2/env/lib/python3.8/site-packages/pyre_check/client/json_rpc.py", line 128, in _read_payload
    line = file.readline()
  File "/usr/lib/python3.8/socket.py", line 669, in readinto
    return self._sock.recv_into(b)
KeyboardInterrupt

2020-10-09 13:16:22,701 WARNING File watching service is down. Results may be inconsistent with full checks. Please run `pyre restart` to bring Pyre server to a consistent state again.

2020-10-09 13:16:35,439 DEBUG Running `/home/dbhost/Work/test_django2/env/bin/pyre.bin stop -log-directory /home/dbhost/Work/test_django2/.pyre /home/dbhost/Work/test_django2/.`
2020-10-09 13:16:35,451 DEBUG Registering process with pid 45099 in pid file `/home/dbhost/Work/test_django2/.pyre/pid_files/stop-45099.pid`
2020-10-09 13:16:40,466 WARNING No servers running

2020-10-09 13:16:40,468 DEBUG Removing pid file: `/home/dbhost/Work/test_django2/.pyre/pid_files/stop-45099.pid`
2020-10-09 13:16:40,469 WARNING Could not stop server. Run `pyre kill` if you want to force-kill all existing servers.

2020-10-09 13:16:40,469 DEBUG Could not stop the file_monitor because it was not found.
2020-10-09 13:16:40,469 DEBUG Could not stop the configuration_monitor because it was not found.
2020-10-09 13:16:40,470 WARNING File watching service is down. Results may be inconsistent with full checks. Please run `pyre restart` to bring Pyre server to a consistent state again.

2020-10-09 13:16:50,997 WARNING Saving the output of `pyre rage` into `/tmp/pyre-rage-ayypcd91.log`

2020-10-09 13:16:51,020 DEBUG Trying to acquire lock on file /home/dbhost/Work/test_django2/.pyre/recently-used-local-configurations.lock
2020-10-09 13:16:51,020 DEBUG No existing file `/home/dbhost/Work/test_django2/.pyre/recently-used-local-configurations.json`.
2020-10-09 13:16:51,021 DEBUG Running `/home/dbhost/Work/test_django2/env/bin/pyre.bin rage -log-directory /home/dbhost/Work/test_django2/.pyre .`
2020-10-09 13:16:51,024 DEBUG Registering process with pid 45161 in pid file `/home/dbhost/Work/test_django2/.pyre/pid_files/rage-45161.pid`
2020-10-09 13:16:51,103 DEBUG /bin/sh: 1: hg: not found
2020-10-09 13:16:51,104 DEBUG /bin/sh: 1: hg: not found
2020-10-09 13:16:51,105 DEBUG /bin/sh: 1: hg: not found
2020-10-09 13:16:51,106 DEBUG /bin/sh: 1: hg: not found
2020-10-09 13:16:51,108 DEBUG Removing pid file: `/home/dbhost/Work/test_django2/.pyre/pid_files/rage-45161.pid`
2020-10-09 13:16:51,109 WARNING Force-killing all running pyre servers.

2020-10-09 13:16:51,109 WARNING Use `pyre servers stop` if you want to gracefully stop all running servers.

2020-10-09 13:16:51,140 INFO Killing process pyre.bin with pid 44849.
2020-10-09 13:16:51,141 INFO Killing process pyre.bin with pid 44850.
2020-10-09 13:16:51,141 INFO Killing process pyre.bin with pid 45157.
2020-10-09 13:16:51,141 INFO Deleting server files under /home/dbhost/Work/test_django2/.pyre
2020-10-09 13:16:51,144 DEBUG Could not find scratch path because of exception: [Errno 2] No such file or directory: 'mkscratch'
2020-10-09 13:16:51,144 DEBUG Error while trying to delete recently-used cache files: [Errno 2] No such file or directory: '/home/dbhost/Work/test_django2/.pyre/recently-used-local-configurations.json'.
2020-10-09 13:16:51,174 DEBUG Could not stop the file_monitor because it was not found.
2020-10-09 13:16:51,174 DEBUG Could not stop the configuration_monitor because it was not found.
2020-10-09 13:16:57,077 INFO Starting server at `/home/dbhost/Work/test_django2/.`.
2020-10-09 13:16:57,078 DEBUG Trying to acquire lock on file /home/dbhost/Work/test_django2/.pyre/client.lock
2020-10-09 13:16:57,078 DEBUG Daemonizing the configuration_monitor.
2020-10-09 13:16:57,078 DEBUG Trying to acquire lock on file /home/dbhost/Work/test_django2/.pyre/server/server.lock
2020-10-09 13:16:57,079 DEBUG Running `/home/dbhost/Work/test_django2/env/bin/pyre.bin start -logging-sections environment -project-root /home/dbhost/Work/test_django2 -log-directory /home/dbhost/Work/test_django2/.pyre -taint-models /home/dbhost/Work/test_django2/env/lib -filter-directories /home/dbhost/Work/test_django2/. -workers 1 -expected-binary-version unversioned -search-path /home/dbhost/Work/test_django2/env/lib/pyre_check/typeshed/stdlib/3.9,/home/dbhost/Work/test_django2/env/lib/pyre_check/typeshed/stdlib/3.7,/home/dbhost/Work/test_django2/env/lib/pyre_check/typeshed/stdlib/3.6,/home/dbhost/Work/test_django2/env/lib/pyre_check/typeshed/stdlib/3,/home/dbhost/Work/test_django2/env/lib/pyre_check/typeshed/stdlib/2and3,/home/dbhost/Work/test_django2/env/lib/pyre_check/typeshed/third_party/3,/home/dbhost/Work/test_django2/env/lib/pyre_check/typeshed/third_party/2and3 -new-incremental-check /home/dbhost/Work/test_django2/.`
2020-10-09 13:16:57,083 DEBUG Trying to acquire lock on file /home/dbhost/Work/test_django2/.pyre/configuration_monitor/configuration_monitor.lock
2020-10-09 13:16:57,084 DEBUG Registering process with pid 45179 in pid file `/home/dbhost/Work/test_django2/.pyre/configuration_monitor/configuration_monitor.pid`
2020-10-09 13:16:57,089 DEBUG Registering process with pid 45178 in pid file `/home/dbhost/Work/test_django2/.pyre/pid_files/start-45178.pid`
2020-10-09 13:16:57,101 INFO Starting up server ...
2020-10-09 13:16:57,101 INFO Running as pid: 45178
2020-10-09 13:16:57,101 INFO Version: f319efebe90e67e4220339e10efa6ee3155537ad
2020-10-09 13:16:57,101 INFO Build info: Linux x86_64 @ Thu Sep 24 17:22:29 PDT 2020
2020-10-09 13:16:57,102 INFO Server starting in background
2020-10-09 13:16:57,102 DEBUG Removing pid file: `/home/dbhost/Work/test_django2/.pyre/pid_files/start-45178.pid`
2020-10-09 13:17:02,486 DEBUG Removing pid file: `/home/dbhost/Work/test_django2/.pyre/configuration_monitor/configuration_monitor.pid`
2020-10-09 13:17:02,487 WARNING Interrupted by user

2020-10-09 13:17:02,487 WARNING Interrupted by user

2020-10-09 13:17:02,488 DEBUG Traceback (most recent call last):
  File "/home/dbhost/Work/test_django2/env/lib/python3.8/site-packages/pyre_check/client/pyre.py", line 125, in run_pyre
    exit_code = command.run().exit_code()
  File "/home/dbhost/Work/test_django2/env/lib/python3.8/site-packages/pyre_check/client/commands/command.py", line 407, in run
    self._run()
  File "/home/dbhost/Work/test_django2/env/lib/python3.8/site-packages/pyre_check/client/commands/incremental.py", line 106, in _run
    Start(
  File "/home/dbhost/Work/test_django2/env/lib/python3.8/site-packages/pyre_check/client/commands/command.py", line 407, in run
    self._run()
  File "/home/dbhost/Work/test_django2/env/lib/python3.8/site-packages/pyre_check/client/commands/start.py", line 116, in _run
    self._start_configuration_monitor()
  File "/home/dbhost/Work/test_django2/env/lib/python3.8/site-packages/pyre_check/client/commands/start.py", line 98, in _start_configuration_monitor
    configuration_monitor.ConfigurationMonitor(
  File "/home/dbhost/Work/test_django2/env/lib/python3.8/site-packages/pyre_check/client/watchman.py", line 159, in daemonize
    self._run()
  File "/home/dbhost/Work/test_django2/env/lib/python3.8/site-packages/pyre_check/client/watchman.py", line 129, in _run
    response = connection.receive()
  File "/home/dbhost/Work/test_django2/env/lib/python3.8/site-packages/pywatchman/__init__.py", line 695, in receive
    buf = [self.transport.readBytes(sniff_len)]
  File "/home/dbhost/Work/test_django2/env/lib/python3.8/site-packages/pywatchman/__init__.py", line 339, in readBytes
    buf = [self.sock.recv(size)]
KeyboardInterrupt

2020-10-09 13:17:02,489 DEBUG Traceback (most recent call last):
  File "/home/dbhost/Work/test_django2/env/lib/python3.8/site-packages/pyre_check/client/pyre.py", line 125, in run_pyre
    exit_code = command.run().exit_code()
  File "/home/dbhost/Work/test_django2/env/lib/python3.8/site-packages/pyre_check/client/commands/command.py", line 407, in run
    self._run()
  File "/home/dbhost/Work/test_django2/env/lib/python3.8/site-packages/pyre_check/client/commands/incremental.py", line 106, in _run
    Start(
  File "/home/dbhost/Work/test_django2/env/lib/python3.8/site-packages/pyre_check/client/commands/command.py", line 407, in run
    self._run()
  File "/home/dbhost/Work/test_django2/env/lib/python3.8/site-packages/pyre_check/client/commands/start.py", line 143, in _run
    file_monitor = project_files_monitor.ProjectFilesMonitor(
  File "/home/dbhost/Work/test_django2/env/lib/python3.8/site-packages/pyre_check/client/project_files_monitor.py", line 66, in __init__
    self.socket_connection.perform_handshake(self._configuration.version_hash)
  File "/home/dbhost/Work/test_django2/env/lib/python3.8/site-packages/pyre_check/client/socket_connection.py", line 45, in perform_handshake
    json_rpc.perform_handshake(self.input, self.output, version_hash)
  File "/home/dbhost/Work/test_django2/env/lib/python3.8/site-packages/pyre_check/client/json_rpc.py", line 168, in perform_handshake
    server_handshake = read_request(input_file)
  File "/home/dbhost/Work/test_django2/env/lib/python3.8/site-packages/pyre_check/client/json_rpc.py", line 144, in read_request
    payload = _read_payload(file)
  File "/home/dbhost/Work/test_django2/env/lib/python3.8/site-packages/pyre_check/client/json_rpc.py", line 128, in _read_payload
    line = file.readline()
  File "/usr/lib/python3.8/socket.py", line 669, in readinto
    return self._sock.recv_into(b)
KeyboardInterrupt

2020-10-09 13:17:05,057 WARNING Saving the output of `pyre rage` into `/tmp/pyre-rage-hgvvfym2.log`

2020-10-09 13:17:05,079 DEBUG Trying to acquire lock on file /home/dbhost/Work/test_django2/.pyre/recently-used-local-configurations.lock
2020-10-09 13:17:05,080 DEBUG No existing file `/home/dbhost/Work/test_django2/.pyre/recently-used-local-configurations.json`.
2020-10-09 13:17:05,081 DEBUG Running `/home/dbhost/Work/test_django2/env/bin/pyre.bin rage -log-directory /home/dbhost/Work/test_django2/.pyre .`
2020-10-09 13:17:05,085 DEBUG Registering process with pid 45202 in pid file `/home/dbhost/Work/test_django2/.pyre/pid_files/rage-45202.pid`
2020-10-09 13:17:05,159 DEBUG /bin/sh: 1: hg: not found
2020-10-09 13:17:05,161 DEBUG /bin/sh: 1: hg: not found
2020-10-09 13:17:05,163 DEBUG /bin/sh: 1: hg: not found
2020-10-09 13:17:05,164 DEBUG /bin/sh: 1: hg: not found
2020-10-09 13:17:05,165 DEBUG Removing pid file: `/home/dbhost/Work/test_django2/.pyre/pid_files/rage-45202.pid`
2020-10-09 13:17:05,166 WARNING Force-killing all running pyre servers.

2020-10-09 13:17:05,166 WARNING Use `pyre servers stop` if you want to gracefully stop all running servers.

2020-10-09 13:17:05,198 INFO Killing process pyre.bin with pid 45185.
2020-10-09 13:17:05,199 INFO Killing process pyre.bin with pid 45186.
2020-10-09 13:17:05,200 INFO Killing process pyre.bin with pid 45198.
2020-10-09 13:17:05,200 INFO Deleting server files under /home/dbhost/Work/test_django2/.pyre
2020-10-09 13:17:05,203 DEBUG Could not find scratch path because of exception: [Errno 2] No such file or directory: 'mkscratch'
2020-10-09 13:17:05,203 DEBUG Error while trying to delete recently-used cache files: [Errno 2] No such file or directory: '/home/dbhost/Work/test_django2/.pyre/recently-used-local-configurations.json'.
2020-10-09 13:17:05,230 DEBUG Could not stop the file_monitor because it was not found.
2020-10-09 13:17:05,230 DEBUG Could not stop the configuration_monitor because it was not found.
2020-10-09 13:17:21,904 INFO Starting server at `/home/dbhost/Work/test_django2/.`.
2020-10-09 13:17:21,904 DEBUG Trying to acquire lock on file /home/dbhost/Work/test_django2/.pyre/client.lock
2020-10-09 13:17:21,904 DEBUG Daemonizing the configuration_monitor.
2020-10-09 13:17:21,905 DEBUG Trying to acquire lock on file /home/dbhost/Work/test_django2/.pyre/server/server.lock
2020-10-09 13:17:21,906 DEBUG Running `/home/dbhost/Work/test_django2/env/bin/pyre.bin start -logging-sections environment -project-root /home/dbhost/Work/test_django2 -log-directory /home/dbhost/Work/test_django2/.pyre -taint-models /home/dbhost/Work/test_django2/env/lib -filter-directories /home/dbhost/Work/test_django2/. -workers 1 -expected-binary-version unversioned -search-path /home/dbhost/Work/test_django2/env/lib/pyre_check/typeshed/stdlib/3.9,/home/dbhost/Work/test_django2/env/lib/pyre_check/typeshed/stdlib/3.7,/home/dbhost/Work/test_django2/env/lib/pyre_check/typeshed/stdlib/3.6,/home/dbhost/Work/test_django2/env/lib/pyre_check/typeshed/stdlib/3,/home/dbhost/Work/test_django2/env/lib/pyre_check/typeshed/stdlib/2and3,/home/dbhost/Work/test_django2/env/lib/pyre_check/typeshed/third_party/3,/home/dbhost/Work/test_django2/env/lib/pyre_check/typeshed/third_party/2and3 -new-incremental-check /home/dbhost/Work/test_django2/.`
2020-10-09 13:17:21,908 DEBUG Trying to acquire lock on file /home/dbhost/Work/test_django2/.pyre/configuration_monitor/configuration_monitor.lock
2020-10-09 13:17:21,909 DEBUG Registering process with pid 45233 in pid file `/home/dbhost/Work/test_django2/.pyre/configuration_monitor/configuration_monitor.pid`
2020-10-09 13:17:21,910 DEBUG Registering process with pid 45232 in pid file `/home/dbhost/Work/test_django2/.pyre/pid_files/start-45232.pid`
2020-10-09 13:17:21,933 INFO Starting up server ...
2020-10-09 13:17:21,933 INFO Running as pid: 45232
2020-10-09 13:17:21,933 INFO Version: f319efebe90e67e4220339e10efa6ee3155537ad
2020-10-09 13:17:21,934 INFO Build info: Linux x86_64 @ Thu Sep 24 17:22:29 PDT 2020
2020-10-09 13:17:21,934 INFO Server starting in background
2020-10-09 13:17:21,936 DEBUG Removing pid file: `/home/dbhost/Work/test_django2/.pyre/pid_files/start-45232.pid`
2020-10-09 13:17:26,548 DEBUG Removing pid file: `/home/dbhost/Work/test_django2/.pyre/configuration_monitor/configuration_monitor.pid`
2020-10-09 13:17:26,548 WARNING Interrupted by user

2020-10-09 13:17:26,548 WARNING Interrupted by user

2020-10-09 13:17:26,550 DEBUG Traceback (most recent call last):
  File "/home/dbhost/Work/test_django2/env/lib/python3.8/site-packages/pyre_check/client/pyre.py", line 125, in run_pyre
    exit_code = command.run().exit_code()
  File "/home/dbhost/Work/test_django2/env/lib/python3.8/site-packages/pyre_check/client/commands/command.py", line 407, in run
    self._run()
  File "/home/dbhost/Work/test_django2/env/lib/python3.8/site-packages/pyre_check/client/commands/incremental.py", line 106, in _run
    Start(
  File "/home/dbhost/Work/test_django2/env/lib/python3.8/site-packages/pyre_check/client/commands/command.py", line 407, in run
    self._run()
  File "/home/dbhost/Work/test_django2/env/lib/python3.8/site-packages/pyre_check/client/commands/start.py", line 116, in _run
    self._start_configuration_monitor()
  File "/home/dbhost/Work/test_django2/env/lib/python3.8/site-packages/pyre_check/client/commands/start.py", line 98, in _start_configuration_monitor
    configuration_monitor.ConfigurationMonitor(
  File "/home/dbhost/Work/test_django2/env/lib/python3.8/site-packages/pyre_check/client/watchman.py", line 159, in daemonize
    self._run()
  File "/home/dbhost/Work/test_django2/env/lib/python3.8/site-packages/pyre_check/client/watchman.py", line 129, in _run
    response = connection.receive()
  File "/home/dbhost/Work/test_django2/env/lib/python3.8/site-packages/pywatchman/__init__.py", line 695, in receive
    buf = [self.transport.readBytes(sniff_len)]
  File "/home/dbhost/Work/test_django2/env/lib/python3.8/site-packages/pywatchman/__init__.py", line 339, in readBytes
    buf = [self.sock.recv(size)]
KeyboardInterrupt

2020-10-09 13:17:26,550 DEBUG Traceback (most recent call last):
  File "/home/dbhost/Work/test_django2/env/lib/python3.8/site-packages/pyre_check/client/pyre.py", line 125, in run_pyre
    exit_code = command.run().exit_code()
  File "/home/dbhost/Work/test_django2/env/lib/python3.8/site-packages/pyre_check/client/commands/command.py", line 407, in run
    self._run()
  File "/home/dbhost/Work/test_django2/env/lib/python3.8/site-packages/pyre_check/client/commands/incremental.py", line 106, in _run
    Start(
  File "/home/dbhost/Work/test_django2/env/lib/python3.8/site-packages/pyre_check/client/commands/command.py", line 407, in run
    self._run()
  File "/home/dbhost/Work/test_django2/env/lib/python3.8/site-packages/pyre_check/client/commands/start.py", line 143, in _run
    file_monitor = project_files_monitor.ProjectFilesMonitor(
  File "/home/dbhost/Work/test_django2/env/lib/python3.8/site-packages/pyre_check/client/project_files_monitor.py", line 66, in __init__
    self.socket_connection.perform_handshake(self._configuration.version_hash)
  File "/home/dbhost/Work/test_django2/env/lib/python3.8/site-packages/pyre_check/client/socket_connection.py", line 45, in perform_handshake
    json_rpc.perform_handshake(self.input, self.output, version_hash)
  File "/home/dbhost/Work/test_django2/env/lib/python3.8/site-packages/pyre_check/client/json_rpc.py", line 168, in perform_handshake
    server_handshake = read_request(input_file)
  File "/home/dbhost/Work/test_django2/env/lib/python3.8/site-packages/pyre_check/client/json_rpc.py", line 144, in read_request
    payload = _read_payload(file)
  File "/home/dbhost/Work/test_django2/env/lib/python3.8/site-packages/pyre_check/client/json_rpc.py", line 128, in _read_payload
    line = file.readline()
  File "/usr/lib/python3.8/socket.py", line 669, in readinto
    return self._sock.recv_into(b)
KeyboardInterrupt

2020-10-09 13:17:58,616 WARNING Saving the output of `pyre rage` into `/tmp/pyre-rage-jdffgm22.log`

2020-10-09 13:17:58,635 DEBUG Trying to acquire lock on file /home/dbhost/Work/test_django2/.pyre/recently-used-local-configurations.lock
2020-10-09 13:17:58,635 DEBUG No existing file `/home/dbhost/Work/test_django2/.pyre/recently-used-local-configurations.json`.
2020-10-09 13:17:58,636 DEBUG Running `/home/dbhost/Work/test_django2/env/bin/pyre.bin rage -log-directory /home/dbhost/Work/test_django2/.pyre .`
2020-10-09 13:17:58,639 DEBUG Registering process with pid 45309 in pid file `/home/dbhost/Work/test_django2/.pyre/pid_files/rage-45309.pid`
2020-10-09 13:17:58,709 DEBUG /bin/sh: 1: hg: not found
2020-10-09 13:17:58,711 DEBUG /bin/sh: 1: hg: not found
2020-10-09 13:17:58,712 DEBUG /bin/sh: 1: hg: not found
2020-10-09 13:17:58,714 DEBUG /bin/sh: 1: hg: not found
2020-10-09 13:17:58,716 DEBUG Removing pid file: `/home/dbhost/Work/test_django2/.pyre/pid_files/rage-45309.pid`
2020-10-09 13:17:58,716 WARNING Force-killing all running pyre servers.

2020-10-09 13:17:58,717 WARNING Use `pyre servers stop` if you want to gracefully stop all running servers.

2020-10-09 13:17:58,747 INFO Killing process pyre.bin with pid 45239.
2020-10-09 13:17:58,748 INFO Killing process pyre.bin with pid 45240.
2020-10-09 13:17:58,749 INFO Killing process pyre.bin with pid 45305.
2020-10-09 13:17:58,750 INFO Deleting server files under /home/dbhost/Work/test_django2/.pyre
2020-10-09 13:17:58,755 DEBUG Could not find scratch path because of exception: [Errno 2] No such file or directory: 'mkscratch'
2020-10-09 13:17:58,756 DEBUG Error while trying to delete recently-used cache files: [Errno 2] No such file or directory: '/home/dbhost/Work/test_django2/.pyre/recently-used-local-configurations.json'.
2020-10-09 13:17:58,789 DEBUG Could not stop the file_monitor because it was not found.
2020-10-09 13:17:58,789 DEBUG Could not stop the configuration_monitor because it was not found.
2020-10-09 13:18:03,511 DEBUG Running `/home/dbhost/Work/test_django2/env/bin/pyre.bin check -project-root /home/dbhost/Work/test_django2 -log-directory /home/dbhost/Work/test_django2/.pyre -filter-directories /home/dbhost/Work/test_django2/. -workers 1 -search-path /home/dbhost/Work/test_django2/env/lib/pyre_check/typeshed/stdlib/3.9,/home/dbhost/Work/test_django2/env/lib/pyre_check/typeshed/stdlib/3.7,/home/dbhost/Work/test_django2/env/lib/pyre_check/typeshed/stdlib/3.6,/home/dbhost/Work/test_django2/env/lib/pyre_check/typeshed/stdlib/3,/home/dbhost/Work/test_django2/env/lib/pyre_check/typeshed/stdlib/2and3,/home/dbhost/Work/test_django2/env/lib/pyre_check/typeshed/third_party/3,/home/dbhost/Work/test_django2/env/lib/pyre_check/typeshed/third_party/2and3 /home/dbhost/Work/test_django2/.`
2020-10-09 13:18:03,515 DEBUG Registering process with pid 45323 in pid file `/home/dbhost/Work/test_django2/.pyre/pid_files/check-45323.pid`
2020-10-09 13:18:04,005 PERFORMANCE Module tracker built: 0.472416s
2020-10-09 13:18:04,005 INFO Building type environment...
2020-10-09 13:18:04,143 INFO Parsing 12279 stubs and sources...
2020-10-09 13:18:09,492 DEBUG Removing pid file: `/home/dbhost/Work/test_django2/.pyre/pid_files/check-45323.pid`
2020-10-09 13:18:09,492 WARNING Interrupted by user

2020-10-09 13:18:09,494 DEBUG Traceback (most recent call last):
  File "/home/dbhost/Work/test_django2/env/lib/python3.8/site-packages/pyre_check/client/pyre.py", line 125, in run_pyre
    exit_code = command.run().exit_code()
  File "/home/dbhost/Work/test_django2/env/lib/python3.8/site-packages/pyre_check/client/commands/command.py", line 407, in run
    self._run()
  File "/home/dbhost/Work/test_django2/env/lib/python3.8/site-packages/pyre_check/client/commands/check.py", line 106, in _run
    result = self._call_client(command="check")
  File "/home/dbhost/Work/test_django2/env/lib/python3.8/site-packages/pyre_check/client/commands/command.py", line 530, in _call_client
    process.wait()
  File "/usr/lib/python3.8/subprocess.py", line 1079, in wait
    return self._wait(timeout=timeout)
  File "/usr/lib/python3.8/subprocess.py", line 1804, in _wait
    (pid, sts) = self._try_wait(0)
  File "/usr/lib/python3.8/subprocess.py", line 1762, in _try_wait
    (pid, sts) = os.waitpid(self.pid, wait_flags)
KeyboardInterrupt

